[2025-01-10 16:14:29,434: INFO: main: Welcome to our custom logging for project 1]
[2025-01-10 16:15:55,916: INFO: main: Welcome to our custom logging for project 1]
[2025-01-10 16:15:57,887: INFO: main: Welcome to our custom logging for project 1]
[2025-01-13 15:43:03,619: INFO: main: >>>>>>> stage Data Ingestion Stage started <<<<<<<<]
[2025-01-13 15:43:03,626: INFO: common: yaml file: config\config.yaml loaded successfully.]
[2025-01-13 15:43:03,629: INFO: common: yaml file: params.yaml loaded successfully.]
[2025-01-13 15:43:03,631: INFO: common: yaml file: schema.yaml loaded successfully.]
[2025-01-13 15:43:05,360: INFO: data_ingestion: artifacts/data_ingestion/data.zip download! with following info: 
Connection: close
Content-Length: 23329
Cache-Control: max-age=300
Content-Security-Policy: default-src 'none'; style-src 'unsafe-inline'; sandbox
Content-Type: application/zip
ETag: "c69888a4ae59bc5a893392785a938ccd4937981c06ba8a9d6a21aa52b4ab5b6e"
Strict-Transport-Security: max-age=31536000
X-Content-Type-Options: nosniff
X-Frame-Options: deny
X-XSS-Protection: 1; mode=block
X-GitHub-Request-Id: BC01:1F4F13:5BE47C:78E7C7:6784E70A
Accept-Ranges: bytes
Date: Mon, 13 Jan 2025 10:12:28 GMT
Via: 1.1 varnish
X-Served-By: cache-bom4749-BOM
X-Cache: MISS
X-Cache-Hits: 0
X-Timer: S1736763148.811108,VS0,VE375
Vary: Authorization,Accept-Encoding,Origin
Access-Control-Allow-Origin: *
Cross-Origin-Resource-Policy: cross-origin
X-Fastly-Request-ID: 5a583135d6e8dc12a3deaeca26f76e905012ed9b
Expires: Mon, 13 Jan 2025 10:17:28 GMT
Source-Age: 0

]
[2025-01-13 15:43:05,379: INFO: main: >>>>>>> stage Data Ingestion Stage completed <<<<<<<<

x==========x]
[2025-01-13 16:26:07,732: INFO: main: >>>>>>> stage Data Ingestion Stage started <<<<<<<<]
[2025-01-13 16:26:07,745: INFO: common: yaml file: config\config.yaml loaded successfully.]
[2025-01-13 16:26:07,750: INFO: common: yaml file: params.yaml loaded successfully.]
[2025-01-13 16:26:07,758: INFO: common: yaml file: schema.yaml loaded successfully.]
[2025-01-13 16:26:07,763: INFO: data_ingestion: File already exists of size: 23329]
[2025-01-13 16:26:07,771: INFO: main: >>>>>>> stage Data Ingestion Stage completed <<<<<<<<

x==========x]
[2025-01-13 16:26:07,778: INFO: main: >>>>>>> stage Data Validation Stage started <<<<<<<<]
[2025-01-13 16:26:07,784: INFO: common: yaml file: config\config.yaml loaded successfully.]
[2025-01-13 16:26:07,787: INFO: common: yaml file: params.yaml loaded successfully.]
[2025-01-13 16:26:07,805: INFO: common: yaml file: schema.yaml loaded successfully.]
[2025-01-13 16:26:07,815: ERROR: main: 'NoneType' object has no attribute 'unzip_data_dir']
Traceback (most recent call last):
  File "E:\udemy\project_1\main.py", line 24, in <module>
    obj.initiate_data_validation()
  File "E:\udemy\project_1\src\project_1\pipeline\data_validation_pipeline.py", line 15, in initiate_data_validation
    data_validation.validate_dataset_columns()
  File "E:\udemy\project_1\src\project_1\components\data_validation.py", line 33, in validate_dataset_columns
    raise e
  File "E:\udemy\project_1\src\project_1\components\data_validation.py", line 15, in validate_dataset_columns
    data=pd.read_csv(self.config.unzip_data_dir)
AttributeError: 'NoneType' object has no attribute 'unzip_data_dir'
[2025-01-13 16:29:00,139: INFO: main: >>>>>>> stage Data Ingestion Stage started <<<<<<<<]
[2025-01-13 16:29:00,142: INFO: common: yaml file: config\config.yaml loaded successfully.]
[2025-01-13 16:29:00,146: INFO: common: yaml file: params.yaml loaded successfully.]
[2025-01-13 16:29:00,150: INFO: common: yaml file: schema.yaml loaded successfully.]
[2025-01-13 16:29:00,152: INFO: data_ingestion: File already exists of size: 23329]
[2025-01-13 16:29:00,156: INFO: main: >>>>>>> stage Data Ingestion Stage completed <<<<<<<<

x==========x]
[2025-01-13 16:29:00,157: INFO: main: >>>>>>> stage Data Validation Stage started <<<<<<<<]
[2025-01-13 16:29:00,165: INFO: common: yaml file: config\config.yaml loaded successfully.]
[2025-01-13 16:29:00,168: INFO: common: yaml file: params.yaml loaded successfully.]
[2025-01-13 16:29:00,172: INFO: common: yaml file: schema.yaml loaded successfully.]
[2025-01-13 16:29:00,181: ERROR: main: 'NoneType' object has no attribute 'unzip_data_dir']
Traceback (most recent call last):
  File "E:\udemy\project_1\main.py", line 24, in <module>
    obj.initiate_data_validation()
  File "E:\udemy\project_1\src\project_1\pipeline\data_validation_pipeline.py", line 15, in initiate_data_validation
    data_validation.validate_dataset_columns()
  File "E:\udemy\project_1\src\project_1\components\data_validation.py", line 33, in validate_dataset_columns
    raise e
  File "E:\udemy\project_1\src\project_1\components\data_validation.py", line 15, in validate_dataset_columns
    data=pd.read_csv(self.config.unzip_data_dir)
AttributeError: 'NoneType' object has no attribute 'unzip_data_dir'
[2025-01-13 16:34:00,675: INFO: main: >>>>>>> stage Data Ingestion Stage started <<<<<<<<]
[2025-01-13 16:34:00,678: INFO: common: yaml file: config\config.yaml loaded successfully.]
[2025-01-13 16:34:00,679: INFO: common: yaml file: params.yaml loaded successfully.]
[2025-01-13 16:34:00,683: INFO: common: yaml file: schema.yaml loaded successfully.]
[2025-01-13 16:34:00,684: INFO: data_ingestion: File already exists of size: 23329]
[2025-01-13 16:34:00,691: INFO: main: >>>>>>> stage Data Ingestion Stage completed <<<<<<<<

x==========x]
[2025-01-13 16:34:00,693: INFO: main: >>>>>>> stage Data Validation Stage started <<<<<<<<]
[2025-01-13 16:34:00,699: INFO: common: yaml file: config\config.yaml loaded successfully.]
[2025-01-13 16:34:00,713: INFO: common: yaml file: params.yaml loaded successfully.]
[2025-01-13 16:34:00,766: INFO: common: yaml file: schema.yaml loaded successfully.]
[2025-01-13 16:34:00,799: ERROR: main: 'NoneType' object has no attribute 'unzip_data_dir']
Traceback (most recent call last):
  File "E:\udemy\project_1\main.py", line 24, in <module>
    data_validation.initiate_data_validation()
  File "E:\udemy\project_1\src\project_1\pipeline\data_validation_pipeline.py", line 15, in initiate_data_validation
    data_validation.validate_dataset_columns()
  File "E:\udemy\project_1\src\project_1\components\data_validation.py", line 33, in validate_dataset_columns
    raise e
  File "E:\udemy\project_1\src\project_1\components\data_validation.py", line 15, in validate_dataset_columns
    data = pd.read_csv(self.config.unzip_data_dir)
AttributeError: 'NoneType' object has no attribute 'unzip_data_dir'
[2025-01-13 16:40:06,635: INFO: main: >>>>>>> stage Data Ingestion Stage started <<<<<<<<]
[2025-01-13 16:40:06,638: INFO: common: yaml file: config\config.yaml loaded successfully.]
[2025-01-13 16:40:06,639: INFO: common: yaml file: params.yaml loaded successfully.]
[2025-01-13 16:40:06,645: INFO: common: yaml file: schema.yaml loaded successfully.]
[2025-01-13 16:40:06,647: INFO: data_ingestion: File already exists of size: 23329]
[2025-01-13 16:40:06,654: INFO: main: >>>>>>> stage Data Ingestion Stage completed <<<<<<<<

x==========x]
[2025-01-13 16:40:06,655: INFO: main: >>>>>>> stage Data Validation Stage started <<<<<<<<]
[2025-01-13 16:40:06,660: INFO: common: yaml file: config\config.yaml loaded successfully.]
[2025-01-13 16:40:06,667: INFO: common: yaml file: params.yaml loaded successfully.]
[2025-01-13 16:40:06,671: INFO: common: yaml file: schema.yaml loaded successfully.]
[2025-01-13 16:40:06,672: ERROR: main: 'DataValidation' object has no attribute 'validate_dataset_columns']
Traceback (most recent call last):
  File "E:\udemy\project_1\main.py", line 24, in <module>
    data_validation.initiate_data_validation()
  File "E:\udemy\project_1\src\project_1\pipeline\data_validation_pipeline.py", line 15, in initiate_data_validation
    data_validation.validate_dataset_columns()
AttributeError: 'DataValidation' object has no attribute 'validate_dataset_columns'
[2025-01-13 16:40:39,694: INFO: main: >>>>>>> stage Data Ingestion Stage started <<<<<<<<]
[2025-01-13 16:40:39,697: INFO: common: yaml file: config\config.yaml loaded successfully.]
[2025-01-13 16:40:39,699: INFO: common: yaml file: params.yaml loaded successfully.]
[2025-01-13 16:40:39,706: INFO: common: yaml file: schema.yaml loaded successfully.]
[2025-01-13 16:40:39,711: INFO: data_ingestion: File already exists of size: 23329]
[2025-01-13 16:40:39,717: INFO: main: >>>>>>> stage Data Ingestion Stage completed <<<<<<<<

x==========x]
[2025-01-13 16:40:39,718: INFO: main: >>>>>>> stage Data Validation Stage started <<<<<<<<]
[2025-01-13 16:40:39,723: INFO: common: yaml file: config\config.yaml loaded successfully.]
[2025-01-13 16:40:39,725: INFO: common: yaml file: params.yaml loaded successfully.]
[2025-01-13 16:40:39,731: INFO: common: yaml file: schema.yaml loaded successfully.]
[2025-01-13 16:40:39,732: ERROR: main: 'NoneType' object has no attribute 'unzip_data_dir']
Traceback (most recent call last):
  File "E:\udemy\project_1\main.py", line 24, in <module>
    data_validation.initiate_data_validation()
  File "E:\udemy\project_1\src\project_1\pipeline\data_validation_pipeline.py", line 15, in initiate_data_validation
    data_validation.validate_all_columns()
  File "E:\udemy\project_1\src\project_1\components\data_validation.py", line 34, in validate_all_columns
    raise e
  File "E:\udemy\project_1\src\project_1\components\data_validation.py", line 15, in validate_all_columns
    data = pd.read_csv(self.config.unzip_data_dir)
AttributeError: 'NoneType' object has no attribute 'unzip_data_dir'
[2025-01-13 16:41:35,282: INFO: main: >>>>>>> stage Data Ingestion Stage started <<<<<<<<]
[2025-01-13 16:41:35,286: INFO: common: yaml file: config\config.yaml loaded successfully.]
[2025-01-13 16:41:35,289: INFO: common: yaml file: params.yaml loaded successfully.]
[2025-01-13 16:41:35,294: INFO: common: yaml file: schema.yaml loaded successfully.]
[2025-01-13 16:41:35,296: INFO: data_ingestion: File already exists of size: 23329]
[2025-01-13 16:41:35,302: INFO: main: >>>>>>> stage Data Ingestion Stage completed <<<<<<<<

x==========x]
[2025-01-13 16:41:35,303: INFO: main: >>>>>>> stage Data Validation Stage started <<<<<<<<]
[2025-01-13 16:41:35,319: INFO: common: yaml file: config\config.yaml loaded successfully.]
[2025-01-13 16:41:35,322: INFO: common: yaml file: params.yaml loaded successfully.]
[2025-01-13 16:41:35,330: INFO: common: yaml file: schema.yaml loaded successfully.]
[2025-01-13 16:41:35,331: ERROR: main: 'NoneType' object has no attribute 'unzip_data_dir']
Traceback (most recent call last):
  File "E:\udemy\project_1\main.py", line 24, in <module>
    data_validation.initiate_data_validation()
  File "E:\udemy\project_1\src\project_1\pipeline\data_validation_pipeline.py", line 15, in initiate_data_validation
    data_validation.validate_all_columns()
  File "E:\udemy\project_1\src\project_1\components\data_validation.py", line 34, in validate_all_columns
    raise e
  File "E:\udemy\project_1\src\project_1\components\data_validation.py", line 15, in validate_all_columns
    data = pd.read_csv(self.config.unzip_data_dir)
AttributeError: 'NoneType' object has no attribute 'unzip_data_dir'
[2025-01-13 16:44:10,296: INFO: main: >>>>>>> stage Data Ingestion Stage started <<<<<<<<]
[2025-01-13 16:44:10,299: INFO: common: yaml file: config\config.yaml loaded successfully.]
[2025-01-13 16:44:10,300: INFO: common: yaml file: params.yaml loaded successfully.]
[2025-01-13 16:44:10,310: INFO: common: yaml file: schema.yaml loaded successfully.]
[2025-01-13 16:44:10,314: INFO: data_ingestion: File already exists of size: 23329]
[2025-01-13 16:44:10,320: INFO: main: >>>>>>> stage Data Ingestion Stage completed <<<<<<<<

x==========x]
[2025-01-13 16:44:10,322: INFO: main: >>>>>>> stage Data Validation Stage started <<<<<<<<]
[2025-01-13 16:44:10,326: INFO: common: yaml file: config\config.yaml loaded successfully.]
[2025-01-13 16:44:10,328: INFO: common: yaml file: params.yaml loaded successfully.]
[2025-01-13 16:44:10,334: INFO: common: yaml file: schema.yaml loaded successfully.]
[2025-01-13 16:44:10,335: ERROR: main: local variable 'config' referenced before assignment]
Traceback (most recent call last):
  File "E:\udemy\project_1\main.py", line 24, in <module>
    data_validation.initiate_data_validation()
  File "E:\udemy\project_1\src\project_1\pipeline\data_validation_pipeline.py", line 13, in initiate_data_validation
    data_validation_config = config.get_data_validation_config()
  File "E:\udemy\project_1\src\project_1\config\configuration.py", line 29, in get_data_validation_config
    config=config.data_validation
UnboundLocalError: local variable 'config' referenced before assignment
[2025-01-13 16:45:32,336: INFO: main: >>>>>>> stage Data Ingestion Stage started <<<<<<<<]
[2025-01-13 16:45:32,339: INFO: common: yaml file: config\config.yaml loaded successfully.]
[2025-01-13 16:45:32,340: INFO: common: yaml file: params.yaml loaded successfully.]
[2025-01-13 16:45:32,349: INFO: common: yaml file: schema.yaml loaded successfully.]
[2025-01-13 16:45:32,352: INFO: data_ingestion: File already exists of size: 23329]
[2025-01-13 16:45:32,359: INFO: main: >>>>>>> stage Data Ingestion Stage completed <<<<<<<<

x==========x]
[2025-01-13 16:45:32,361: INFO: main: >>>>>>> stage Data Validation Stage started <<<<<<<<]
[2025-01-13 16:45:32,366: INFO: common: yaml file: config\config.yaml loaded successfully.]
[2025-01-13 16:45:32,367: INFO: common: yaml file: params.yaml loaded successfully.]
[2025-01-13 16:45:32,372: INFO: common: yaml file: schema.yaml loaded successfully.]
[2025-01-13 16:45:32,407: INFO: main: >>>>>>> stage Data Validation Stage completed <<<<<<<<

x==========x]
[2025-01-13 17:17:47,379: INFO: main: >>>>>>> stage Data Ingestion Stage started <<<<<<<<]
[2025-01-13 17:17:47,384: INFO: common: yaml file: config\config.yaml loaded successfully.]
[2025-01-13 17:17:47,386: INFO: common: yaml file: params.yaml loaded successfully.]
[2025-01-13 17:17:47,398: INFO: common: yaml file: schema.yaml loaded successfully.]
[2025-01-13 17:17:47,401: INFO: data_ingestion: File already exists of size: 23329]
[2025-01-13 17:17:47,405: INFO: main: >>>>>>> stage Data Ingestion Stage completed <<<<<<<<

x==========x]
[2025-01-13 17:17:47,406: INFO: main: >>>>>>> stage Data Validation Stage started <<<<<<<<]
[2025-01-13 17:17:47,414: INFO: common: yaml file: config\config.yaml loaded successfully.]
[2025-01-13 17:17:47,420: INFO: common: yaml file: params.yaml loaded successfully.]
[2025-01-13 17:17:47,425: INFO: common: yaml file: schema.yaml loaded successfully.]
[2025-01-13 17:17:47,457: INFO: main: >>>>>>> stage Data Validation Stage completed <<<<<<<<

x==========x]
[2025-01-13 17:17:47,458: INFO: main: >>>>>>> stage Data Transformation Stage started <<<<<<<<]
[2025-01-13 17:17:47,464: INFO: common: yaml file: config\config.yaml loaded successfully.]
[2025-01-13 17:17:47,466: INFO: common: yaml file: params.yaml loaded successfully.]
[2025-01-13 17:17:47,471: INFO: common: yaml file: schema.yaml loaded successfully.]
[2025-01-13 17:17:47,524: INFO: data_transformation: Splited data into train and test]
[2025-01-13 17:17:47,525: INFO: data_transformation: (1199, 12)]
[2025-01-13 17:17:47,526: INFO: data_transformation: (400, 12)]
[2025-01-13 17:17:47,529: INFO: main: >>>>>>> stage Data Transformation Stage completed <<<<<<<<

x==========x]
[2025-01-13 17:18:16,991: INFO: main: >>>>>>> stage Data Ingestion Stage started <<<<<<<<]
[2025-01-13 17:18:16,996: INFO: common: yaml file: config\config.yaml loaded successfully.]
[2025-01-13 17:18:16,998: INFO: common: yaml file: params.yaml loaded successfully.]
[2025-01-13 17:18:17,013: INFO: common: yaml file: schema.yaml loaded successfully.]
[2025-01-13 17:18:17,018: INFO: data_ingestion: File already exists of size: 23329]
[2025-01-13 17:18:17,023: INFO: main: >>>>>>> stage Data Ingestion Stage completed <<<<<<<<

x==========x]
[2025-01-13 17:18:17,027: INFO: main: >>>>>>> stage Data Validation Stage started <<<<<<<<]
[2025-01-13 17:18:17,036: INFO: common: yaml file: config\config.yaml loaded successfully.]
[2025-01-13 17:18:17,038: INFO: common: yaml file: params.yaml loaded successfully.]
[2025-01-13 17:18:17,045: INFO: common: yaml file: schema.yaml loaded successfully.]
[2025-01-13 17:18:17,086: INFO: main: >>>>>>> stage Data Validation Stage completed <<<<<<<<

x==========x]
[2025-01-13 17:18:17,087: INFO: main: >>>>>>> stage Data Transformation Stage started <<<<<<<<]
[2025-01-13 17:18:17,097: INFO: common: yaml file: config\config.yaml loaded successfully.]
[2025-01-13 17:18:17,100: INFO: common: yaml file: params.yaml loaded successfully.]
[2025-01-13 17:18:17,107: INFO: common: yaml file: schema.yaml loaded successfully.]
[2025-01-13 17:18:17,157: INFO: data_transformation: Splited data into train and test]
[2025-01-13 17:18:17,164: INFO: data_transformation: (1199, 12)]
[2025-01-13 17:18:17,167: INFO: data_transformation: (400, 12)]
[2025-01-13 17:18:17,173: INFO: main: >>>>>>> stage Data Transformation Stage completed <<<<<<<<

x==========x]
[2025-01-13 21:01:30,605: INFO: main: >>>>>>> stage Data Ingestion Stage started <<<<<<<<]
[2025-01-13 21:01:30,613: INFO: common: yaml file: config\config.yaml loaded successfully.]
[2025-01-13 21:01:30,621: INFO: common: yaml file: params.yaml loaded successfully.]
[2025-01-13 21:01:30,631: INFO: common: yaml file: schema.yaml loaded successfully.]
[2025-01-13 21:01:30,634: INFO: data_ingestion: File already exists of size: 23329]
[2025-01-13 21:01:30,651: INFO: main: >>>>>>> stage Data Ingestion Stage completed <<<<<<<<

x==========x]
[2025-01-13 21:01:30,652: INFO: main: >>>>>>> stage Data Validation Stage started <<<<<<<<]
[2025-01-13 21:01:30,661: INFO: common: yaml file: config\config.yaml loaded successfully.]
[2025-01-13 21:01:30,670: INFO: common: yaml file: params.yaml loaded successfully.]
[2025-01-13 21:01:30,685: INFO: common: yaml file: schema.yaml loaded successfully.]
[2025-01-13 21:01:30,768: INFO: main: >>>>>>> stage Data Validation Stage completed <<<<<<<<

x==========x]
[2025-01-13 21:01:30,780: INFO: main: >>>>>>> stage Data Transformation Stage started <<<<<<<<]
[2025-01-13 21:01:30,813: INFO: common: yaml file: config\config.yaml loaded successfully.]
[2025-01-13 21:01:30,823: INFO: common: yaml file: params.yaml loaded successfully.]
[2025-01-13 21:01:30,827: INFO: common: yaml file: schema.yaml loaded successfully.]
[2025-01-13 21:01:30,918: INFO: data_transformation: Splited data into train and test]
[2025-01-13 21:01:30,919: INFO: data_transformation: (1199, 12)]
[2025-01-13 21:01:30,919: INFO: data_transformation: (400, 12)]
[2025-01-13 21:01:30,921: INFO: main: >>>>>>> stage Data Transformation Stage completed <<<<<<<<

x==========x]
[2025-01-13 21:01:30,922: INFO: main: >>>>>>> stage Model Training Stage started <<<<<<<<]
[2025-01-13 21:01:30,926: INFO: common: yaml file: config\config.yaml loaded successfully.]
[2025-01-13 21:01:30,930: INFO: common: yaml file: params.yaml loaded successfully.]
[2025-01-13 21:01:30,935: INFO: common: yaml file: schema.yaml loaded successfully.]
[2025-01-13 21:01:30,937: ERROR: main: "'ConfigBox' object has no attribute 'elasticnet'"]
Traceback (most recent call last):
  File "box\\box.py", line 593, in box.box.Box.__getitem__
KeyError: 'ElasticNet'

The above exception was the direct cause of the following exception:

Traceback (most recent call last):
  File "box\\box.py", line 632, in box.box.Box.__getattr__
  File "box\\box.py", line 620, in box.box.Box.__getitem__
box.exceptions.BoxKeyError: "'ElasticNet'"

During handling of the above exception, another exception occurred:

Traceback (most recent call last):
  File "box\\box.py", line 634, in box.box.Box.__getattr__
AttributeError: 'ConfigBox' object has no attribute 'ElasticNet'

The above exception was the direct cause of the following exception:

Traceback (most recent call last):
  File "box\\config_box.py", line 29, in box.config_box.ConfigBox.__getattr__
  File "box\\box.py", line 648, in box.box.Box.__getattr__
box.exceptions.BoxKeyError: "'ConfigBox' object has no attribute 'ElasticNet'"

During handling of the above exception, another exception occurred:

Traceback (most recent call last):
  File "box\\box.py", line 593, in box.box.Box.__getitem__
KeyError: 'elasticnet'

The above exception was the direct cause of the following exception:

Traceback (most recent call last):
  File "box\\box.py", line 632, in box.box.Box.__getattr__
  File "box\\box.py", line 620, in box.box.Box.__getitem__
box.exceptions.BoxKeyError: "'elasticnet'"

During handling of the above exception, another exception occurred:

Traceback (most recent call last):
  File "box\\box.py", line 634, in box.box.Box.__getattr__
AttributeError: 'ConfigBox' object has no attribute 'elasticnet'

The above exception was the direct cause of the following exception:

Traceback (most recent call last):
  File "E:\udemy\project_1\main.py", line 51, in <module>
    obj.initiate_model_trainer()
  File "E:\udemy\project_1\src\project_1\pipeline\model_trainer_pipeline.py", line 13, in initiate_model_trainer
    model_trainer_config = config.get_model_trainer_config()
  File "E:\udemy\project_1\src\project_1\config\configuration.py", line 56, in get_model_trainer_config
    params=self.config.ElasticNet
  File "box\\config_box.py", line 31, in box.config_box.ConfigBox.__getattr__
  File "box\\box.py", line 648, in box.box.Box.__getattr__
box.exceptions.BoxKeyError: "'ConfigBox' object has no attribute 'elasticnet'"
[2025-01-13 21:02:35,358: INFO: main: >>>>>>> stage Data Ingestion Stage started <<<<<<<<]
[2025-01-13 21:02:35,364: INFO: common: yaml file: config\config.yaml loaded successfully.]
[2025-01-13 21:02:35,367: INFO: common: yaml file: params.yaml loaded successfully.]
[2025-01-13 21:02:35,379: INFO: common: yaml file: schema.yaml loaded successfully.]
[2025-01-13 21:02:35,383: INFO: data_ingestion: File already exists of size: 23329]
[2025-01-13 21:02:35,388: INFO: main: >>>>>>> stage Data Ingestion Stage completed <<<<<<<<

x==========x]
[2025-01-13 21:02:35,390: INFO: main: >>>>>>> stage Data Validation Stage started <<<<<<<<]
[2025-01-13 21:02:35,400: INFO: common: yaml file: config\config.yaml loaded successfully.]
[2025-01-13 21:02:35,402: INFO: common: yaml file: params.yaml loaded successfully.]
[2025-01-13 21:02:35,408: INFO: common: yaml file: schema.yaml loaded successfully.]
[2025-01-13 21:02:35,457: INFO: main: >>>>>>> stage Data Validation Stage completed <<<<<<<<

x==========x]
[2025-01-13 21:02:35,463: INFO: main: >>>>>>> stage Data Transformation Stage started <<<<<<<<]
[2025-01-13 21:02:35,477: INFO: common: yaml file: config\config.yaml loaded successfully.]
[2025-01-13 21:02:35,490: INFO: common: yaml file: params.yaml loaded successfully.]
[2025-01-13 21:02:35,504: INFO: common: yaml file: schema.yaml loaded successfully.]
[2025-01-13 21:02:35,598: INFO: data_transformation: Splited data into train and test]
[2025-01-13 21:02:35,600: INFO: data_transformation: (1199, 12)]
[2025-01-13 21:02:35,602: INFO: data_transformation: (400, 12)]
[2025-01-13 21:02:35,609: INFO: main: >>>>>>> stage Data Transformation Stage completed <<<<<<<<

x==========x]
[2025-01-13 21:02:35,618: INFO: main: >>>>>>> stage Model Training Stage started <<<<<<<<]
[2025-01-13 21:02:35,640: INFO: common: yaml file: config\config.yaml loaded successfully.]
[2025-01-13 21:02:35,648: INFO: common: yaml file: params.yaml loaded successfully.]
[2025-01-13 21:02:35,660: INFO: common: yaml file: schema.yaml loaded successfully.]
[2025-01-13 21:02:35,664: ERROR: main: 'ConfigurationManager' object has no attribute 'root_dir']
Traceback (most recent call last):
  File "E:\udemy\project_1\main.py", line 51, in <module>
    obj.initiate_model_trainer()
  File "E:\udemy\project_1\src\project_1\pipeline\model_trainer_pipeline.py", line 13, in initiate_model_trainer
    model_trainer_config = config.get_model_trainer_config()
  File "E:\udemy\project_1\src\project_1\config\configuration.py", line 58, in get_model_trainer_config
    create_directories([self.root_dir])
AttributeError: 'ConfigurationManager' object has no attribute 'root_dir'
[2025-01-13 21:03:15,156: INFO: main: >>>>>>> stage Data Ingestion Stage started <<<<<<<<]
[2025-01-13 21:03:15,162: INFO: common: yaml file: config\config.yaml loaded successfully.]
[2025-01-13 21:03:15,165: INFO: common: yaml file: params.yaml loaded successfully.]
[2025-01-13 21:03:15,175: INFO: common: yaml file: schema.yaml loaded successfully.]
[2025-01-13 21:03:15,177: INFO: data_ingestion: File already exists of size: 23329]
[2025-01-13 21:03:15,262: INFO: main: >>>>>>> stage Data Ingestion Stage completed <<<<<<<<

x==========x]
[2025-01-13 21:03:15,268: INFO: main: >>>>>>> stage Data Validation Stage started <<<<<<<<]
[2025-01-13 21:03:15,318: INFO: common: yaml file: config\config.yaml loaded successfully.]
[2025-01-13 21:03:15,330: INFO: common: yaml file: params.yaml loaded successfully.]
[2025-01-13 21:03:15,365: INFO: common: yaml file: schema.yaml loaded successfully.]
[2025-01-13 21:03:15,402: INFO: main: >>>>>>> stage Data Validation Stage completed <<<<<<<<

x==========x]
[2025-01-13 21:03:15,408: INFO: main: >>>>>>> stage Data Transformation Stage started <<<<<<<<]
[2025-01-13 21:03:15,414: INFO: common: yaml file: config\config.yaml loaded successfully.]
[2025-01-13 21:03:15,416: INFO: common: yaml file: params.yaml loaded successfully.]
[2025-01-13 21:03:15,421: INFO: common: yaml file: schema.yaml loaded successfully.]
[2025-01-13 21:03:15,465: INFO: data_transformation: Splited data into train and test]
[2025-01-13 21:03:15,465: INFO: data_transformation: (1199, 12)]
[2025-01-13 21:03:15,466: INFO: data_transformation: (400, 12)]
[2025-01-13 21:03:15,467: INFO: main: >>>>>>> stage Data Transformation Stage completed <<<<<<<<

x==========x]
[2025-01-13 21:03:15,468: INFO: main: >>>>>>> stage Model Training Stage started <<<<<<<<]
[2025-01-13 21:03:15,479: INFO: common: yaml file: config\config.yaml loaded successfully.]
[2025-01-13 21:03:15,483: INFO: common: yaml file: params.yaml loaded successfully.]
[2025-01-13 21:03:15,494: INFO: common: yaml file: schema.yaml loaded successfully.]
[2025-01-13 21:03:15,496: ERROR: main: "'ConfigBox' object has no attribute 'root_dir'"]
Traceback (most recent call last):
  File "box\\box.py", line 593, in box.box.Box.__getitem__
KeyError: 'root_dir'

The above exception was the direct cause of the following exception:

Traceback (most recent call last):
  File "box\\box.py", line 632, in box.box.Box.__getattr__
  File "box\\box.py", line 620, in box.box.Box.__getitem__
box.exceptions.BoxKeyError: "'root_dir'"

During handling of the above exception, another exception occurred:

Traceback (most recent call last):
  File "box\\box.py", line 634, in box.box.Box.__getattr__
AttributeError: 'ConfigBox' object has no attribute 'root_dir'

The above exception was the direct cause of the following exception:

Traceback (most recent call last):
  File "box\\config_box.py", line 29, in box.config_box.ConfigBox.__getattr__
  File "box\\box.py", line 648, in box.box.Box.__getattr__
box.exceptions.BoxKeyError: "'ConfigBox' object has no attribute 'root_dir'"

During handling of the above exception, another exception occurred:

Traceback (most recent call last):
  File "box\\box.py", line 593, in box.box.Box.__getitem__
KeyError: 'root_dir'

The above exception was the direct cause of the following exception:

Traceback (most recent call last):
  File "box\\box.py", line 632, in box.box.Box.__getattr__
  File "box\\box.py", line 620, in box.box.Box.__getitem__
box.exceptions.BoxKeyError: "'root_dir'"

During handling of the above exception, another exception occurred:

Traceback (most recent call last):
  File "box\\box.py", line 634, in box.box.Box.__getattr__
AttributeError: 'ConfigBox' object has no attribute 'root_dir'

The above exception was the direct cause of the following exception:

Traceback (most recent call last):
  File "E:\udemy\project_1\main.py", line 51, in <module>
    obj.initiate_model_trainer()
  File "E:\udemy\project_1\src\project_1\pipeline\model_trainer_pipeline.py", line 13, in initiate_model_trainer
    model_trainer_config = config.get_model_trainer_config()
  File "E:\udemy\project_1\src\project_1\config\configuration.py", line 58, in get_model_trainer_config
    create_directories([self.config.root_dir])
  File "box\\config_box.py", line 31, in box.config_box.ConfigBox.__getattr__
  File "box\\box.py", line 648, in box.box.Box.__getattr__
box.exceptions.BoxKeyError: "'ConfigBox' object has no attribute 'root_dir'"
[2025-01-13 21:08:38,658: INFO: main: >>>>>>> stage Data Ingestion Stage started <<<<<<<<]
[2025-01-13 21:08:38,667: INFO: common: yaml file: config\config.yaml loaded successfully.]
[2025-01-13 21:08:38,671: INFO: common: yaml file: params.yaml loaded successfully.]
[2025-01-13 21:08:38,678: INFO: common: yaml file: schema.yaml loaded successfully.]
[2025-01-13 21:08:38,681: INFO: data_ingestion: File already exists of size: 23329]
[2025-01-13 21:08:38,688: INFO: main: >>>>>>> stage Data Ingestion Stage completed <<<<<<<<

x==========x]
[2025-01-13 21:08:38,689: INFO: main: >>>>>>> stage Data Validation Stage started <<<<<<<<]
[2025-01-13 21:08:38,695: INFO: common: yaml file: config\config.yaml loaded successfully.]
[2025-01-13 21:08:38,703: INFO: common: yaml file: params.yaml loaded successfully.]
[2025-01-13 21:08:38,707: INFO: common: yaml file: schema.yaml loaded successfully.]
[2025-01-13 21:08:38,758: INFO: main: >>>>>>> stage Data Validation Stage completed <<<<<<<<

x==========x]
[2025-01-13 21:08:38,760: INFO: main: >>>>>>> stage Data Transformation Stage started <<<<<<<<]
[2025-01-13 21:08:38,789: INFO: common: yaml file: config\config.yaml loaded successfully.]
[2025-01-13 21:08:38,791: INFO: common: yaml file: params.yaml loaded successfully.]
[2025-01-13 21:08:38,799: INFO: common: yaml file: schema.yaml loaded successfully.]
[2025-01-13 21:08:38,844: INFO: data_transformation: Splited data into train and test]
[2025-01-13 21:08:38,844: INFO: data_transformation: (1199, 12)]
[2025-01-13 21:08:38,845: INFO: data_transformation: (400, 12)]
[2025-01-13 21:08:38,851: INFO: main: >>>>>>> stage Data Transformation Stage completed <<<<<<<<

x==========x]
[2025-01-13 21:08:38,853: INFO: main: >>>>>>> stage Model Training Stage started <<<<<<<<]
[2025-01-13 21:08:38,858: INFO: common: yaml file: config\config.yaml loaded successfully.]
[2025-01-13 21:08:38,860: INFO: common: yaml file: params.yaml loaded successfully.]
[2025-01-13 21:08:38,870: INFO: common: yaml file: schema.yaml loaded successfully.]
[2025-01-13 21:08:38,872: ERROR: main: "'ConfigBox' object has no attribute 'root_dir'"]
Traceback (most recent call last):
  File "box\\box.py", line 593, in box.box.Box.__getitem__
KeyError: 'root_dir'

The above exception was the direct cause of the following exception:

Traceback (most recent call last):
  File "box\\box.py", line 632, in box.box.Box.__getattr__
  File "box\\box.py", line 620, in box.box.Box.__getitem__
box.exceptions.BoxKeyError: "'root_dir'"

During handling of the above exception, another exception occurred:

Traceback (most recent call last):
  File "box\\box.py", line 634, in box.box.Box.__getattr__
AttributeError: 'ConfigBox' object has no attribute 'root_dir'

The above exception was the direct cause of the following exception:

Traceback (most recent call last):
  File "box\\config_box.py", line 29, in box.config_box.ConfigBox.__getattr__
  File "box\\box.py", line 648, in box.box.Box.__getattr__
box.exceptions.BoxKeyError: "'ConfigBox' object has no attribute 'root_dir'"

During handling of the above exception, another exception occurred:

Traceback (most recent call last):
  File "box\\box.py", line 593, in box.box.Box.__getitem__
KeyError: 'root_dir'

The above exception was the direct cause of the following exception:

Traceback (most recent call last):
  File "box\\box.py", line 632, in box.box.Box.__getattr__
  File "box\\box.py", line 620, in box.box.Box.__getitem__
box.exceptions.BoxKeyError: "'root_dir'"

During handling of the above exception, another exception occurred:

Traceback (most recent call last):
  File "box\\box.py", line 634, in box.box.Box.__getattr__
AttributeError: 'ConfigBox' object has no attribute 'root_dir'

The above exception was the direct cause of the following exception:

Traceback (most recent call last):
  File "E:\udemy\project_1\main.py", line 51, in <module>
    obj.initiate_model_training()
  File "E:\udemy\project_1\src\project_1\pipeline\model_trainer_pipeline.py", line 13, in initiate_model_training
    model_trainer_config = config.get_model_trainer_config()
  File "E:\udemy\project_1\src\project_1\config\configuration.py", line 58, in get_model_trainer_config
    create_directories([self.config.root_dir])
  File "box\\config_box.py", line 31, in box.config_box.ConfigBox.__getattr__
  File "box\\box.py", line 648, in box.box.Box.__getattr__
box.exceptions.BoxKeyError: "'ConfigBox' object has no attribute 'root_dir'"
[2025-01-13 21:10:46,446: INFO: main: >>>>>>> stage Data Ingestion Stage started <<<<<<<<]
[2025-01-13 21:10:46,453: INFO: common: yaml file: config\config.yaml loaded successfully.]
[2025-01-13 21:10:46,457: INFO: common: yaml file: params.yaml loaded successfully.]
[2025-01-13 21:10:46,461: INFO: common: yaml file: schema.yaml loaded successfully.]
[2025-01-13 21:10:46,462: INFO: data_ingestion: File already exists of size: 23329]
[2025-01-13 21:10:46,468: INFO: main: >>>>>>> stage Data Ingestion Stage completed <<<<<<<<

x==========x]
[2025-01-13 21:10:46,472: INFO: main: >>>>>>> stage Data Validation Stage started <<<<<<<<]
[2025-01-13 21:10:46,487: INFO: common: yaml file: config\config.yaml loaded successfully.]
[2025-01-13 21:10:46,493: INFO: common: yaml file: params.yaml loaded successfully.]
[2025-01-13 21:10:46,500: INFO: common: yaml file: schema.yaml loaded successfully.]
[2025-01-13 21:10:46,550: INFO: main: >>>>>>> stage Data Validation Stage completed <<<<<<<<

x==========x]
[2025-01-13 21:10:46,552: INFO: main: >>>>>>> stage Data Transformation Stage started <<<<<<<<]
[2025-01-13 21:10:46,565: INFO: common: yaml file: config\config.yaml loaded successfully.]
[2025-01-13 21:10:46,568: INFO: common: yaml file: params.yaml loaded successfully.]
[2025-01-13 21:10:46,578: INFO: common: yaml file: schema.yaml loaded successfully.]
[2025-01-13 21:10:46,633: INFO: data_transformation: Splited data into train and test]
[2025-01-13 21:10:46,634: INFO: data_transformation: (1199, 12)]
[2025-01-13 21:10:46,635: INFO: data_transformation: (400, 12)]
[2025-01-13 21:10:46,636: INFO: main: >>>>>>> stage Data Transformation Stage completed <<<<<<<<

x==========x]
[2025-01-13 21:10:46,638: INFO: main: >>>>>>> stage Model Training Stage started <<<<<<<<]
[2025-01-13 21:10:46,650: INFO: common: yaml file: config\config.yaml loaded successfully.]
[2025-01-13 21:10:46,653: INFO: common: yaml file: params.yaml loaded successfully.]
[2025-01-13 21:10:46,667: INFO: common: yaml file: schema.yaml loaded successfully.]
[2025-01-13 21:10:46,671: ERROR: main: "'ConfigBox' object has no attribute 'model_name'"]
Traceback (most recent call last):
  File "box\\box.py", line 593, in box.box.Box.__getitem__
KeyError: 'model_name'

The above exception was the direct cause of the following exception:

Traceback (most recent call last):
  File "box\\box.py", line 632, in box.box.Box.__getattr__
  File "box\\box.py", line 620, in box.box.Box.__getitem__
box.exceptions.BoxKeyError: "'model_name'"

During handling of the above exception, another exception occurred:

Traceback (most recent call last):
  File "box\\box.py", line 634, in box.box.Box.__getattr__
AttributeError: 'ConfigBox' object has no attribute 'model_name'

The above exception was the direct cause of the following exception:

Traceback (most recent call last):
  File "box\\config_box.py", line 29, in box.config_box.ConfigBox.__getattr__
  File "box\\box.py", line 648, in box.box.Box.__getattr__
box.exceptions.BoxKeyError: "'ConfigBox' object has no attribute 'model_name'"

During handling of the above exception, another exception occurred:

Traceback (most recent call last):
  File "box\\box.py", line 593, in box.box.Box.__getitem__
KeyError: 'model_name'

The above exception was the direct cause of the following exception:

Traceback (most recent call last):
  File "box\\box.py", line 632, in box.box.Box.__getattr__
  File "box\\box.py", line 620, in box.box.Box.__getitem__
box.exceptions.BoxKeyError: "'model_name'"

During handling of the above exception, another exception occurred:

Traceback (most recent call last):
  File "box\\box.py", line 634, in box.box.Box.__getattr__
AttributeError: 'ConfigBox' object has no attribute 'model_name'

The above exception was the direct cause of the following exception:

Traceback (most recent call last):
  File "E:\udemy\project_1\main.py", line 51, in <module>
    obj.initiate_model_training()
  File "E:\udemy\project_1\src\project_1\pipeline\model_trainer_pipeline.py", line 13, in initiate_model_training
    model_trainer_config = config.get_model_trainer_config()
  File "E:\udemy\project_1\src\project_1\config\configuration.py", line 64, in get_model_trainer_config
    model_name = config.model_name,
  File "box\\config_box.py", line 31, in box.config_box.ConfigBox.__getattr__
  File "box\\box.py", line 648, in box.box.Box.__getattr__
box.exceptions.BoxKeyError: "'ConfigBox' object has no attribute 'model_name'"
[2025-01-13 21:12:33,740: INFO: main: >>>>>>> stage Data Ingestion Stage started <<<<<<<<]
[2025-01-13 21:12:33,747: INFO: common: yaml file: config\config.yaml loaded successfully.]
[2025-01-13 21:12:33,750: INFO: common: yaml file: params.yaml loaded successfully.]
[2025-01-13 21:12:33,758: INFO: common: yaml file: schema.yaml loaded successfully.]
[2025-01-13 21:12:33,760: INFO: data_ingestion: File already exists of size: 23329]
[2025-01-13 21:12:33,767: INFO: main: >>>>>>> stage Data Ingestion Stage completed <<<<<<<<

x==========x]
[2025-01-13 21:12:33,769: INFO: main: >>>>>>> stage Data Validation Stage started <<<<<<<<]
[2025-01-13 21:12:33,786: INFO: common: yaml file: config\config.yaml loaded successfully.]
[2025-01-13 21:12:33,788: INFO: common: yaml file: params.yaml loaded successfully.]
[2025-01-13 21:12:33,792: INFO: common: yaml file: schema.yaml loaded successfully.]
[2025-01-13 21:12:33,832: INFO: main: >>>>>>> stage Data Validation Stage completed <<<<<<<<

x==========x]
[2025-01-13 21:12:33,835: INFO: main: >>>>>>> stage Data Transformation Stage started <<<<<<<<]
[2025-01-13 21:12:33,841: INFO: common: yaml file: config\config.yaml loaded successfully.]
[2025-01-13 21:12:33,843: INFO: common: yaml file: params.yaml loaded successfully.]
[2025-01-13 21:12:33,853: INFO: common: yaml file: schema.yaml loaded successfully.]
[2025-01-13 21:12:33,895: INFO: data_transformation: Splited data into train and test]
[2025-01-13 21:12:33,897: INFO: data_transformation: (1199, 12)]
[2025-01-13 21:12:33,900: INFO: data_transformation: (400, 12)]
[2025-01-13 21:12:33,902: INFO: main: >>>>>>> stage Data Transformation Stage completed <<<<<<<<

x==========x]
[2025-01-13 21:12:33,903: INFO: main: >>>>>>> stage Model Training Stage started <<<<<<<<]
[2025-01-13 21:12:33,909: INFO: common: yaml file: config\config.yaml loaded successfully.]
[2025-01-13 21:12:33,911: INFO: common: yaml file: params.yaml loaded successfully.]
[2025-01-13 21:12:33,918: INFO: common: yaml file: schema.yaml loaded successfully.]
[2025-01-13 21:12:33,920: ERROR: main: "'ConfigBox' object has no attribute 'model_name'"]
Traceback (most recent call last):
  File "box\\box.py", line 593, in box.box.Box.__getitem__
KeyError: 'model_name'

The above exception was the direct cause of the following exception:

Traceback (most recent call last):
  File "box\\box.py", line 632, in box.box.Box.__getattr__
  File "box\\box.py", line 620, in box.box.Box.__getitem__
box.exceptions.BoxKeyError: "'model_name'"

During handling of the above exception, another exception occurred:

Traceback (most recent call last):
  File "box\\box.py", line 634, in box.box.Box.__getattr__
AttributeError: 'ConfigBox' object has no attribute 'model_name'

The above exception was the direct cause of the following exception:

Traceback (most recent call last):
  File "box\\config_box.py", line 29, in box.config_box.ConfigBox.__getattr__
  File "box\\box.py", line 648, in box.box.Box.__getattr__
box.exceptions.BoxKeyError: "'ConfigBox' object has no attribute 'model_name'"

During handling of the above exception, another exception occurred:

Traceback (most recent call last):
  File "box\\box.py", line 593, in box.box.Box.__getitem__
KeyError: 'model_name'

The above exception was the direct cause of the following exception:

Traceback (most recent call last):
  File "box\\box.py", line 632, in box.box.Box.__getattr__
  File "box\\box.py", line 620, in box.box.Box.__getitem__
box.exceptions.BoxKeyError: "'model_name'"

During handling of the above exception, another exception occurred:

Traceback (most recent call last):
  File "box\\box.py", line 634, in box.box.Box.__getattr__
AttributeError: 'ConfigBox' object has no attribute 'model_name'

The above exception was the direct cause of the following exception:

Traceback (most recent call last):
  File "E:\udemy\project_1\main.py", line 51, in <module>
    obj.initiate_model_training()
  File "E:\udemy\project_1\src\project_1\pipeline\model_trainer_pipeline.py", line 13, in initiate_model_training
    model_trainer_config = config.get_model_trainer_config()
  File "E:\udemy\project_1\src\project_1\config\configuration.py", line 64, in get_model_trainer_config
    model_name = config.model_name,
  File "box\\config_box.py", line 31, in box.config_box.ConfigBox.__getattr__
  File "box\\box.py", line 648, in box.box.Box.__getattr__
box.exceptions.BoxKeyError: "'ConfigBox' object has no attribute 'model_name'"
[2025-01-13 21:13:54,731: INFO: main: >>>>>>> stage Data Ingestion Stage started <<<<<<<<]
[2025-01-13 21:13:54,737: INFO: common: yaml file: config\config.yaml loaded successfully.]
[2025-01-13 21:13:54,739: INFO: common: yaml file: params.yaml loaded successfully.]
[2025-01-13 21:13:54,742: INFO: common: yaml file: schema.yaml loaded successfully.]
[2025-01-13 21:13:54,743: INFO: data_ingestion: File already exists of size: 23329]
[2025-01-13 21:13:54,747: INFO: main: >>>>>>> stage Data Ingestion Stage completed <<<<<<<<

x==========x]
[2025-01-13 21:13:54,748: INFO: main: >>>>>>> stage Data Validation Stage started <<<<<<<<]
[2025-01-13 21:13:54,765: INFO: common: yaml file: config\config.yaml loaded successfully.]
[2025-01-13 21:13:54,768: INFO: common: yaml file: params.yaml loaded successfully.]
[2025-01-13 21:13:54,771: INFO: common: yaml file: schema.yaml loaded successfully.]
[2025-01-13 21:13:54,814: INFO: main: >>>>>>> stage Data Validation Stage completed <<<<<<<<

x==========x]
[2025-01-13 21:13:54,817: INFO: main: >>>>>>> stage Data Transformation Stage started <<<<<<<<]
[2025-01-13 21:13:54,828: INFO: common: yaml file: config\config.yaml loaded successfully.]
[2025-01-13 21:13:54,831: INFO: common: yaml file: params.yaml loaded successfully.]
[2025-01-13 21:13:54,835: INFO: common: yaml file: schema.yaml loaded successfully.]
[2025-01-13 21:13:54,878: INFO: data_transformation: Splited data into train and test]
[2025-01-13 21:13:54,879: INFO: data_transformation: (1199, 12)]
[2025-01-13 21:13:54,880: INFO: data_transformation: (400, 12)]
[2025-01-13 21:13:54,881: INFO: main: >>>>>>> stage Data Transformation Stage completed <<<<<<<<

x==========x]
[2025-01-13 21:13:54,882: INFO: main: >>>>>>> stage Model Training Stage started <<<<<<<<]
[2025-01-13 21:13:54,886: INFO: common: yaml file: config\config.yaml loaded successfully.]
[2025-01-13 21:13:54,894: INFO: common: yaml file: params.yaml loaded successfully.]
[2025-01-13 21:13:54,897: INFO: common: yaml file: schema.yaml loaded successfully.]
[2025-01-13 21:13:54,899: ERROR: main: "'ConfigBox' object has no attribute 'model_name'"]
Traceback (most recent call last):
  File "box\\box.py", line 593, in box.box.Box.__getitem__
KeyError: 'model_name'

The above exception was the direct cause of the following exception:

Traceback (most recent call last):
  File "box\\box.py", line 632, in box.box.Box.__getattr__
  File "box\\box.py", line 620, in box.box.Box.__getitem__
box.exceptions.BoxKeyError: "'model_name'"

During handling of the above exception, another exception occurred:

Traceback (most recent call last):
  File "box\\box.py", line 634, in box.box.Box.__getattr__
AttributeError: 'ConfigBox' object has no attribute 'model_name'

The above exception was the direct cause of the following exception:

Traceback (most recent call last):
  File "box\\config_box.py", line 29, in box.config_box.ConfigBox.__getattr__
  File "box\\box.py", line 648, in box.box.Box.__getattr__
box.exceptions.BoxKeyError: "'ConfigBox' object has no attribute 'model_name'"

During handling of the above exception, another exception occurred:

Traceback (most recent call last):
  File "box\\box.py", line 593, in box.box.Box.__getitem__
KeyError: 'model_name'

The above exception was the direct cause of the following exception:

Traceback (most recent call last):
  File "box\\box.py", line 632, in box.box.Box.__getattr__
  File "box\\box.py", line 620, in box.box.Box.__getitem__
box.exceptions.BoxKeyError: "'model_name'"

During handling of the above exception, another exception occurred:

Traceback (most recent call last):
  File "box\\box.py", line 634, in box.box.Box.__getattr__
AttributeError: 'ConfigBox' object has no attribute 'model_name'

The above exception was the direct cause of the following exception:

Traceback (most recent call last):
  File "E:\udemy\project_1\main.py", line 51, in <module>
    obj.initiate_model_training()
  File "E:\udemy\project_1\src\project_1\pipeline\model_trainer_pipeline.py", line 13, in initiate_model_training
    model_trainer_config = config.get_model_trainer_config()
  File "E:\udemy\project_1\src\project_1\config\configuration.py", line 64, in get_model_trainer_config
    model_name=config.model_name,
  File "box\\config_box.py", line 31, in box.config_box.ConfigBox.__getattr__
  File "box\\box.py", line 648, in box.box.Box.__getattr__
box.exceptions.BoxKeyError: "'ConfigBox' object has no attribute 'model_name'"
[2025-01-13 21:17:53,817: INFO: main: >>>>>>> stage Data Ingestion Stage started <<<<<<<<]
[2025-01-13 21:17:53,826: INFO: common: yaml file: config\config.yaml loaded successfully.]
[2025-01-13 21:17:53,828: INFO: common: yaml file: params.yaml loaded successfully.]
[2025-01-13 21:17:53,833: INFO: common: yaml file: schema.yaml loaded successfully.]
[2025-01-13 21:17:53,834: INFO: data_ingestion: File already exists of size: 23329]
[2025-01-13 21:17:53,841: INFO: main: >>>>>>> stage Data Ingestion Stage completed <<<<<<<<

x==========x]
[2025-01-13 21:17:53,842: INFO: main: >>>>>>> stage Data Validation Stage started <<<<<<<<]
[2025-01-13 21:17:53,853: INFO: common: yaml file: config\config.yaml loaded successfully.]
[2025-01-13 21:17:53,855: INFO: common: yaml file: params.yaml loaded successfully.]
[2025-01-13 21:17:53,864: INFO: common: yaml file: schema.yaml loaded successfully.]
[2025-01-13 21:17:53,899: INFO: main: >>>>>>> stage Data Validation Stage completed <<<<<<<<

x==========x]
[2025-01-13 21:17:53,900: INFO: main: >>>>>>> stage Data Transformation Stage started <<<<<<<<]
[2025-01-13 21:17:53,911: INFO: common: yaml file: config\config.yaml loaded successfully.]
[2025-01-13 21:17:53,914: INFO: common: yaml file: params.yaml loaded successfully.]
[2025-01-13 21:17:53,918: INFO: common: yaml file: schema.yaml loaded successfully.]
[2025-01-13 21:17:53,962: INFO: data_transformation: Splited data into train and test]
[2025-01-13 21:17:53,963: INFO: data_transformation: (1199, 12)]
[2025-01-13 21:17:53,963: INFO: data_transformation: (400, 12)]
[2025-01-13 21:17:53,964: INFO: main: >>>>>>> stage Data Transformation Stage completed <<<<<<<<

x==========x]
[2025-01-13 21:17:53,965: INFO: main: >>>>>>> stage Model Training Stage started <<<<<<<<]
[2025-01-13 21:17:53,970: INFO: common: yaml file: config\config.yaml loaded successfully.]
[2025-01-13 21:17:53,977: INFO: common: yaml file: params.yaml loaded successfully.]
[2025-01-13 21:17:53,981: INFO: common: yaml file: schema.yaml loaded successfully.]
[2025-01-13 21:17:53,982: ERROR: main: "'ConfigBox' object has no attribute 'model_name'"]
Traceback (most recent call last):
  File "box\\box.py", line 593, in box.box.Box.__getitem__
KeyError: 'model_name'

The above exception was the direct cause of the following exception:

Traceback (most recent call last):
  File "box\\box.py", line 632, in box.box.Box.__getattr__
  File "box\\box.py", line 620, in box.box.Box.__getitem__
box.exceptions.BoxKeyError: "'model_name'"

During handling of the above exception, another exception occurred:

Traceback (most recent call last):
  File "box\\box.py", line 634, in box.box.Box.__getattr__
AttributeError: 'ConfigBox' object has no attribute 'model_name'

The above exception was the direct cause of the following exception:

Traceback (most recent call last):
  File "box\\config_box.py", line 29, in box.config_box.ConfigBox.__getattr__
  File "box\\box.py", line 648, in box.box.Box.__getattr__
box.exceptions.BoxKeyError: "'ConfigBox' object has no attribute 'model_name'"

During handling of the above exception, another exception occurred:

Traceback (most recent call last):
  File "box\\box.py", line 593, in box.box.Box.__getitem__
KeyError: 'model_name'

The above exception was the direct cause of the following exception:

Traceback (most recent call last):
  File "box\\box.py", line 632, in box.box.Box.__getattr__
  File "box\\box.py", line 620, in box.box.Box.__getitem__
box.exceptions.BoxKeyError: "'model_name'"

During handling of the above exception, another exception occurred:

Traceback (most recent call last):
  File "box\\box.py", line 634, in box.box.Box.__getattr__
AttributeError: 'ConfigBox' object has no attribute 'model_name'

The above exception was the direct cause of the following exception:

Traceback (most recent call last):
  File "E:\udemy\project_1\main.py", line 51, in <module>
    obj.initiate_model_training()
  File "E:\udemy\project_1\src\project_1\pipeline\model_trainer_pipeline.py", line 13, in initiate_model_training
    model_trainer_config = config.get_model_trainer_config()
  File "E:\udemy\project_1\src\project_1\config\configuration.py", line 64, in get_model_trainer_config
    model_name=config.model_name,
  File "box\\config_box.py", line 31, in box.config_box.ConfigBox.__getattr__
  File "box\\box.py", line 648, in box.box.Box.__getattr__
box.exceptions.BoxKeyError: "'ConfigBox' object has no attribute 'model_name'"
[2025-01-13 21:19:37,171: INFO: main: >>>>>>> stage Data Ingestion Stage started <<<<<<<<]
[2025-01-13 21:19:37,178: INFO: common: yaml file: config\config.yaml loaded successfully.]
[2025-01-13 21:19:37,180: INFO: common: yaml file: params.yaml loaded successfully.]
[2025-01-13 21:19:37,185: INFO: common: yaml file: schema.yaml loaded successfully.]
[2025-01-13 21:19:37,187: INFO: data_ingestion: File already exists of size: 23329]
[2025-01-13 21:19:37,191: INFO: main: >>>>>>> stage Data Ingestion Stage completed <<<<<<<<

x==========x]
[2025-01-13 21:19:37,192: INFO: main: >>>>>>> stage Data Validation Stage started <<<<<<<<]
[2025-01-13 21:19:37,203: INFO: common: yaml file: config\config.yaml loaded successfully.]
[2025-01-13 21:19:37,204: INFO: common: yaml file: params.yaml loaded successfully.]
[2025-01-13 21:19:37,208: INFO: common: yaml file: schema.yaml loaded successfully.]
[2025-01-13 21:19:37,254: INFO: main: >>>>>>> stage Data Validation Stage completed <<<<<<<<

x==========x]
[2025-01-13 21:19:37,255: INFO: main: >>>>>>> stage Data Transformation Stage started <<<<<<<<]
[2025-01-13 21:19:37,261: INFO: common: yaml file: config\config.yaml loaded successfully.]
[2025-01-13 21:19:37,263: INFO: common: yaml file: params.yaml loaded successfully.]
[2025-01-13 21:19:37,273: INFO: common: yaml file: schema.yaml loaded successfully.]
[2025-01-13 21:19:37,320: INFO: data_transformation: Splited data into train and test]
[2025-01-13 21:19:37,321: INFO: data_transformation: (1199, 12)]
[2025-01-13 21:19:37,321: INFO: data_transformation: (400, 12)]
[2025-01-13 21:19:37,322: INFO: main: >>>>>>> stage Data Transformation Stage completed <<<<<<<<

x==========x]
[2025-01-13 21:19:37,323: INFO: main: >>>>>>> stage Model Training Stage started <<<<<<<<]
[2025-01-13 21:19:37,329: INFO: common: yaml file: config\config.yaml loaded successfully.]
[2025-01-13 21:19:37,335: INFO: common: yaml file: params.yaml loaded successfully.]
[2025-01-13 21:19:37,340: INFO: common: yaml file: schema.yaml loaded successfully.]
[2025-01-13 21:19:37,342: ERROR: main: "'ConfigBox' object has no attribute 'model__name'"]
Traceback (most recent call last):
  File "box\\box.py", line 593, in box.box.Box.__getitem__
KeyError: 'model__name'

The above exception was the direct cause of the following exception:

Traceback (most recent call last):
  File "box\\box.py", line 632, in box.box.Box.__getattr__
  File "box\\box.py", line 620, in box.box.Box.__getitem__
box.exceptions.BoxKeyError: "'model__name'"

During handling of the above exception, another exception occurred:

Traceback (most recent call last):
  File "box\\box.py", line 634, in box.box.Box.__getattr__
AttributeError: 'ConfigBox' object has no attribute 'model__name'

The above exception was the direct cause of the following exception:

Traceback (most recent call last):
  File "box\\config_box.py", line 29, in box.config_box.ConfigBox.__getattr__
  File "box\\box.py", line 648, in box.box.Box.__getattr__
box.exceptions.BoxKeyError: "'ConfigBox' object has no attribute 'model__name'"

During handling of the above exception, another exception occurred:

Traceback (most recent call last):
  File "box\\box.py", line 593, in box.box.Box.__getitem__
KeyError: 'model__name'

The above exception was the direct cause of the following exception:

Traceback (most recent call last):
  File "box\\box.py", line 632, in box.box.Box.__getattr__
  File "box\\box.py", line 620, in box.box.Box.__getitem__
box.exceptions.BoxKeyError: "'model__name'"

During handling of the above exception, another exception occurred:

Traceback (most recent call last):
  File "box\\box.py", line 634, in box.box.Box.__getattr__
AttributeError: 'ConfigBox' object has no attribute 'model__name'

The above exception was the direct cause of the following exception:

Traceback (most recent call last):
  File "E:\udemy\project_1\main.py", line 51, in <module>
    obj.initiate_model_training()
  File "E:\udemy\project_1\src\project_1\pipeline\model_trainer_pipeline.py", line 13, in initiate_model_training
    model_trainer_config = config.get_model_trainer_config()
  File "E:\udemy\project_1\src\project_1\config\configuration.py", line 64, in get_model_trainer_config
    model_name=config.model__name,
  File "box\\config_box.py", line 31, in box.config_box.ConfigBox.__getattr__
  File "box\\box.py", line 648, in box.box.Box.__getattr__
box.exceptions.BoxKeyError: "'ConfigBox' object has no attribute 'model__name'"
[2025-01-13 21:22:00,739: INFO: main: >>>>>>> stage Data Ingestion Stage started <<<<<<<<]
[2025-01-13 21:22:00,745: INFO: common: yaml file: config\config.yaml loaded successfully.]
[2025-01-13 21:22:00,748: INFO: common: yaml file: params.yaml loaded successfully.]
[2025-01-13 21:22:00,759: INFO: common: yaml file: schema.yaml loaded successfully.]
[2025-01-13 21:22:00,761: INFO: data_ingestion: File already exists of size: 23329]
[2025-01-13 21:22:00,765: INFO: main: >>>>>>> stage Data Ingestion Stage completed <<<<<<<<

x==========x]
[2025-01-13 21:22:00,766: INFO: main: >>>>>>> stage Data Validation Stage started <<<<<<<<]
[2025-01-13 21:22:00,777: INFO: common: yaml file: config\config.yaml loaded successfully.]
[2025-01-13 21:22:00,779: INFO: common: yaml file: params.yaml loaded successfully.]
[2025-01-13 21:22:00,783: INFO: common: yaml file: schema.yaml loaded successfully.]
[2025-01-13 21:22:00,816: INFO: main: >>>>>>> stage Data Validation Stage completed <<<<<<<<

x==========x]
[2025-01-13 21:22:00,817: INFO: main: >>>>>>> stage Data Transformation Stage started <<<<<<<<]
[2025-01-13 21:22:00,830: INFO: common: yaml file: config\config.yaml loaded successfully.]
[2025-01-13 21:22:00,832: INFO: common: yaml file: params.yaml loaded successfully.]
[2025-01-13 21:22:00,837: INFO: common: yaml file: schema.yaml loaded successfully.]
[2025-01-13 21:22:00,879: INFO: data_transformation: Splited data into train and test]
[2025-01-13 21:22:00,880: INFO: data_transformation: (1199, 12)]
[2025-01-13 21:22:00,880: INFO: data_transformation: (400, 12)]
[2025-01-13 21:22:00,882: INFO: main: >>>>>>> stage Data Transformation Stage completed <<<<<<<<

x==========x]
[2025-01-13 21:22:00,883: INFO: main: >>>>>>> stage Model Training Stage started <<<<<<<<]
[2025-01-13 21:22:00,889: INFO: common: yaml file: config\config.yaml loaded successfully.]
[2025-01-13 21:22:00,893: INFO: common: yaml file: params.yaml loaded successfully.]
[2025-01-13 21:22:00,897: INFO: common: yaml file: schema.yaml loaded successfully.]
[2025-01-13 21:22:00,899: ERROR: main: "'ConfigBox' object has no attribute 'model__name'"]
Traceback (most recent call last):
  File "box\\box.py", line 593, in box.box.Box.__getitem__
KeyError: 'model__name'

The above exception was the direct cause of the following exception:

Traceback (most recent call last):
  File "box\\box.py", line 632, in box.box.Box.__getattr__
  File "box\\box.py", line 620, in box.box.Box.__getitem__
box.exceptions.BoxKeyError: "'model__name'"

During handling of the above exception, another exception occurred:

Traceback (most recent call last):
  File "box\\box.py", line 634, in box.box.Box.__getattr__
AttributeError: 'ConfigBox' object has no attribute 'model__name'

The above exception was the direct cause of the following exception:

Traceback (most recent call last):
  File "box\\config_box.py", line 29, in box.config_box.ConfigBox.__getattr__
  File "box\\box.py", line 648, in box.box.Box.__getattr__
box.exceptions.BoxKeyError: "'ConfigBox' object has no attribute 'model__name'"

During handling of the above exception, another exception occurred:

Traceback (most recent call last):
  File "box\\box.py", line 593, in box.box.Box.__getitem__
KeyError: 'model__name'

The above exception was the direct cause of the following exception:

Traceback (most recent call last):
  File "box\\box.py", line 632, in box.box.Box.__getattr__
  File "box\\box.py", line 620, in box.box.Box.__getitem__
box.exceptions.BoxKeyError: "'model__name'"

During handling of the above exception, another exception occurred:

Traceback (most recent call last):
  File "box\\box.py", line 634, in box.box.Box.__getattr__
AttributeError: 'ConfigBox' object has no attribute 'model__name'

The above exception was the direct cause of the following exception:

Traceback (most recent call last):
  File "E:\udemy\project_1\main.py", line 51, in <module>
    obj.initiate_model_training()
  File "E:\udemy\project_1\src\project_1\pipeline\model_trainer_pipeline.py", line 13, in initiate_model_training
    model_trainer_config = config.get_model_trainer_config()
  File "E:\udemy\project_1\src\project_1\config\configuration.py", line 64, in get_model_trainer_config
    model_name=config.model__name,
  File "box\\config_box.py", line 31, in box.config_box.ConfigBox.__getattr__
  File "box\\box.py", line 648, in box.box.Box.__getattr__
box.exceptions.BoxKeyError: "'ConfigBox' object has no attribute 'model__name'"
[2025-01-13 21:24:45,712: INFO: main: >>>>>>> stage Data Ingestion Stage started <<<<<<<<]
[2025-01-13 21:24:45,718: INFO: common: yaml file: config\config.yaml loaded successfully.]
[2025-01-13 21:24:45,720: INFO: common: yaml file: params.yaml loaded successfully.]
[2025-01-13 21:24:45,728: INFO: common: yaml file: schema.yaml loaded successfully.]
[2025-01-13 21:24:45,729: INFO: data_ingestion: File already exists of size: 23329]
[2025-01-13 21:24:45,739: INFO: main: >>>>>>> stage Data Ingestion Stage completed <<<<<<<<

x==========x]
[2025-01-13 21:24:45,740: INFO: main: >>>>>>> stage Data Validation Stage started <<<<<<<<]
[2025-01-13 21:24:45,748: INFO: common: yaml file: config\config.yaml loaded successfully.]
[2025-01-13 21:24:45,750: INFO: common: yaml file: params.yaml loaded successfully.]
[2025-01-13 21:24:45,755: INFO: common: yaml file: schema.yaml loaded successfully.]
[2025-01-13 21:24:45,802: INFO: main: >>>>>>> stage Data Validation Stage completed <<<<<<<<

x==========x]
[2025-01-13 21:24:45,805: INFO: main: >>>>>>> stage Data Transformation Stage started <<<<<<<<]
[2025-01-13 21:24:45,818: INFO: common: yaml file: config\config.yaml loaded successfully.]
[2025-01-13 21:24:45,820: INFO: common: yaml file: params.yaml loaded successfully.]
[2025-01-13 21:24:45,826: INFO: common: yaml file: schema.yaml loaded successfully.]
[2025-01-13 21:24:45,895: INFO: data_transformation: Splited data into train and test]
[2025-01-13 21:24:45,897: INFO: data_transformation: (1199, 12)]
[2025-01-13 21:24:45,899: INFO: data_transformation: (400, 12)]
[2025-01-13 21:24:45,910: INFO: main: >>>>>>> stage Data Transformation Stage completed <<<<<<<<

x==========x]
[2025-01-13 21:24:45,912: INFO: main: >>>>>>> stage Model Training Stage started <<<<<<<<]
[2025-01-13 21:24:45,921: INFO: common: yaml file: config\config.yaml loaded successfully.]
[2025-01-13 21:24:45,924: INFO: common: yaml file: params.yaml loaded successfully.]
[2025-01-13 21:24:45,932: INFO: common: yaml file: schema.yaml loaded successfully.]
[2025-01-13 21:24:45,935: ERROR: main: ModelTrainerConfig.__init__() got an unexpected keyword argument 'model_name']
Traceback (most recent call last):
  File "E:\udemy\project_1\main.py", line 51, in <module>
    obj.initiate_model_training()
  File "E:\udemy\project_1\src\project_1\pipeline\model_trainer_pipeline.py", line 13, in initiate_model_training
    model_trainer_config = config.get_model_trainer_config()
  File "E:\udemy\project_1\src\project_1\config\configuration.py", line 60, in get_model_trainer_config
    model_trainer_config = ModelTrainerConfig(
TypeError: ModelTrainerConfig.__init__() got an unexpected keyword argument 'model_name'
[2025-01-13 21:25:16,371: INFO: main: >>>>>>> stage Data Ingestion Stage started <<<<<<<<]
[2025-01-13 21:25:16,377: INFO: common: yaml file: config\config.yaml loaded successfully.]
[2025-01-13 21:25:16,380: INFO: common: yaml file: params.yaml loaded successfully.]
[2025-01-13 21:25:16,391: INFO: common: yaml file: schema.yaml loaded successfully.]
[2025-01-13 21:25:16,395: INFO: data_ingestion: File already exists of size: 23329]
[2025-01-13 21:25:16,400: INFO: main: >>>>>>> stage Data Ingestion Stage completed <<<<<<<<

x==========x]
[2025-01-13 21:25:16,401: INFO: main: >>>>>>> stage Data Validation Stage started <<<<<<<<]
[2025-01-13 21:25:16,411: INFO: common: yaml file: config\config.yaml loaded successfully.]
[2025-01-13 21:25:16,415: INFO: common: yaml file: params.yaml loaded successfully.]
[2025-01-13 21:25:16,420: INFO: common: yaml file: schema.yaml loaded successfully.]
[2025-01-13 21:25:16,456: INFO: main: >>>>>>> stage Data Validation Stage completed <<<<<<<<

x==========x]
[2025-01-13 21:25:16,457: INFO: main: >>>>>>> stage Data Transformation Stage started <<<<<<<<]
[2025-01-13 21:25:16,470: INFO: common: yaml file: config\config.yaml loaded successfully.]
[2025-01-13 21:25:16,474: INFO: common: yaml file: params.yaml loaded successfully.]
[2025-01-13 21:25:16,483: INFO: common: yaml file: schema.yaml loaded successfully.]
[2025-01-13 21:25:16,533: INFO: data_transformation: Splited data into train and test]
[2025-01-13 21:25:16,533: INFO: data_transformation: (1199, 12)]
[2025-01-13 21:25:16,534: INFO: data_transformation: (400, 12)]
[2025-01-13 21:25:16,535: INFO: main: >>>>>>> stage Data Transformation Stage completed <<<<<<<<

x==========x]
[2025-01-13 21:25:16,536: INFO: main: >>>>>>> stage Model Training Stage started <<<<<<<<]
[2025-01-13 21:25:16,546: INFO: common: yaml file: config\config.yaml loaded successfully.]
[2025-01-13 21:25:16,549: INFO: common: yaml file: params.yaml loaded successfully.]
[2025-01-13 21:25:16,554: INFO: common: yaml file: schema.yaml loaded successfully.]
[2025-01-13 21:25:16,648: INFO: main: >>>>>>> stage Model Training Stage completed <<<<<<<<

x==========x]
